Workbook

Sheet Modules
A1: Module Code | B1: Module Name | C1: Module Year | D1: Module Term | E1: Programme Code | F1: Stream Code | G1: Enrollment Student Number | H1: Actual Student Number | I1: Proposed Teacher | J1: Teaching Status
A2: HD401 | B2: Introduction to Academic English (CEF) | C2: Y1 | D2: Sep | E2: HDBA | G2: 20 | H2: 10 | I2: =VLOOKUP($A2,Sheet1!$E:$I,4,0) -> Mr Ray Leung | J2: =VLOOKUP($A2,Sheet1!$E:$I,5,0) -> PT
A3: HD401 | B3: Introduction to Academic English (CEF) | C3: Y1 | D3: Sep | E3: HDC | G3: =G2 -> 20 | H3: =H2 -> 10 | I3: =VLOOKUP($A3,Sheet1!$E:$I,4,0) -> Mr Ray Leung | J3: =VLOOKUP($A3,Sheet1!$E:$I,5,0) -> PT
A4: HD401 | B4: Introduction to Academic English (CEF) | C4: Y1 | D4: Sep | E4: HDCI | G4: =G3 -> 20 | H4: =H3 -> 10 | I4: =VLOOKUP($A4,Sheet1!$E:$I,4,0) -> Mr Ray Leung | J4: =VLOOKUP($A4,Sheet1!$E:$I,5,0) -> PT
A5: HD401 | B5: Introduction to Academic English (CEF) | C5: Y1 | D5: Sep | E5: HDEE | G5: =G4 -> 20 | H5: =H4 -> 10 | I5: =VLOOKUP($A5,Sheet1!$E:$I,4,0) -> Mr Ray Leung | J5: =VLOOKUP($A5,Sheet1!$E:$I,5,0) -> PT
A6: HD401 | B6: Introduction to Academic English (CEF) | C6: Y1 | D6: Sep | E6: HDHC | G6: =G5 -> 20 | H6: =H5 -> 10 | I6: =VLOOKUP($A6,Sheet1!$E:$I,4,0) -> Mr Ray Leung | J6: =VLOOKUP($A6,Sheet1!$E:$I,5,0) -> PT
A7: HD404 | B7: Professional Ethics | C7: Y2 | D7: Sep | E7: HDBA | G7: =G6 -> 20 | H7: =H6 -> 10 | I7: =VLOOKUP($A7,Sheet1!$E:$I,4,0) -> Mr Walter Chan | J7: =VLOOKUP($A7,Sheet1!$E:$I,5,0) -> FT
A8: HD404 | B8: Professional Ethics | C8: Y2 | D8: Sep | E8: HDC | G8: =G7 -> 20 | H8: =H7 -> 10 | I8: =VLOOKUP($A8,Sheet1!$E:$I,4,0) -> Mr Walter Chan | J8: =VLOOKUP($A8,Sheet1!$E:$I,5,0) -> FT
A9: HD404 | B9: Professional Ethics | C9: Y2 | D9: Sep | E9: HDCI | G9: =G8 -> 20 | H9: =H8 -> 10 | I9: =VLOOKUP($A9,Sheet1!$E:$I,4,0) -> Mr Walter Chan | J9: =VLOOKUP($A9,Sheet1!$E:$I,5,0) -> FT
A10: HD404 | B10: Professional Ethics | C10: Y2 | D10: Sep | E10: HDEE | G10: =G9 -> 20 | H10: =H9 -> 10 | I10: =VLOOKUP($A10,Sheet1!$E:$I,4,0) -> Mr Walter Chan | J10: =VLOOKUP($A10,Sheet1!$E:$I,5,0) -> FT
A11: HD404 | B11: Professional Ethics | C11: Y2 | D11: Sep | E11: HDHC | G11: =G10 -> 20 | H11: =H10 -> 10 | I11: =VLOOKUP($A11,Sheet1!$E:$I,4,0) -> Mr Walter Chan | J11: =VLOOKUP($A11,Sheet1!$E:$I,5,0) -> FT
A12: HD402 | B12: Practical Chinese (CEF) | C12: Y1 | D12: Feb | E12: HDBA | G12: =G11 -> 20 | H12: =H11 -> 10 | I12: =VLOOKUP($A12,Sheet1!$E:$I,4,0) -> Mr Alan Ho | J12: =VLOOKUP($A12,Sheet1!$E:$I,5,0) -> FT
A13: HD402 | B13: Practical Chinese (CEF) | C13: Y1 | D13: Feb | E13: HDC | G13: =G12 -> 20 | H13: =H12 -> 10 | I13: =VLOOKUP($A13,Sheet1!$E:$I,4,0) -> Mr Alan Ho | J13: =VLOOKUP($A13,Sheet1!$E:$I,5,0) -> FT
A14: HD402 | B14: Practical Chinese (CEF) | C14: Y1 | D14: Feb | E14: HDCI | G14: =G13 -> 20 | H14: =H13 -> 10 | I14: =VLOOKUP($A14,Sheet1!$E:$I,4,0) -> Mr Alan Ho | J14: =VLOOKUP($A14,Sheet1!$E:$I,5,0) -> FT
... A17: HD403 | B17: Project Skills | C17: Y2 | D17: Feb | E17: HDBA | G17: =G16 -> 20 | H17: =H16 -> 10 | I17: =VLOOKUP($A17,Sheet1!$E:$I,4,0) -> Mr Walter Chan | J17: =VLOOKUP($A17,Sheet1!$E:$I,5,0) -> FT
A18: HD403_HDC | B18: Project Skills | C18: Y2 | D18: Feb | E18: HDC | G18: =G17 -> 20 | H18: =H17 -> 10 | I18: Dr HK Ng | J18: FT
A19: HD403 | B19: Project Skills | C19: Y2 | D19: Feb | E19: HDCI | G19: =G18 -> 20 | H19: =H18 -> 10 | I19: =VLOOKUP($A19,Sheet1!$E:$I,4,0) -> Mr Walter Chan | J19: =VLOOKUP($A19,Sheet1!$E:$I,5,0) -> FT
A20: HD403 | B20: Project Skills | C20: Y2 | D20: Feb | E20: HDEE | G20: =G19 -> 20 | H20: =H19 -> 10 | I20: =VLOOKUP($A20,Sheet1!$E:$I,4,0) -> Mr Walter Chan | J20: =VLOOKUP($A20,Sheet1!$E:$I,5,0) -> FT
A21: HD403 | B21: Project Skills | C21: Y2 | D21: Feb | E21: HDHC | G21: =G20 -> 20 | H21: =H20 -> 10 | I21: =VLOOKUP($A21,Sheet1!$E:$I,4,0) -> Mr Walter Chan | J21: =VLOOKUP($A21,Sheet1!$E:$I,5,0) -> FT
A22: HD405 | B22: English for Communication in Workplace | C22: Y2 | D22: Feb | E22: HDBA | G22: =G21 -> 20 | H22: =H21 -> 10 | I22: =VLOOKUP($A22,Sheet1!$E:$I,4,0) -> Mr Richard Cheng | J22: =VLOOKUP($A22,Sheet1!$E:$I,5,0) -> PT
A23: HD405 | B23: English for Communication in Workplace | C23: Y2 | D23: Feb | E23: HDC | G23: =G22 -> 20 | H23: =H22 -> 10 | I23: =VLOOKUP($A23,Sheet1!$E:$I,4,0) -> Mr Richard Cheng | J23: =VLOOKUP($A23,Sheet1!$E:$I,5,0) -> PT
A24: HD405 | B24: English for Communication in Workplace | C24: Y2 | D24: Feb | E24: HDCI | G24: =G23 -> 20 | H24: =H23 -> 10 | I24: =VLOOKUP($A24,Sheet1!$E:$I,4,0) -> Mr Richard Cheng | J24: =VLOOKUP($A24,Sheet1!$E:$I,5,0) -> PT
A25: HD405 | B25: English for Communication in Workplace | C25: Y2 | D25: Feb | E25: HDEE | G25: =G24 -> 20 | H25: =H24 -> 10 | I25: =VLOOKUP($A25,Sheet1!$E:$I,4,0) -> Mr Richard Cheng | J25: =VLOOKUP($A25,Sheet1!$E:$I,5,0) -> PT
A26: HD405 | B26: English for Communication in Workplace | C26: Y2 | D26: Feb | E26: HDHC | G26: =G25 -> 20 | H26: =H25 -> 10 | I26: =VLOOKUP($A26,Sheet1!$E:$I,4,0) -> Mr Richard Cheng | J26: =VLOOKUP($A26,Sheet1!$E:$I,5,0) -> PT
A27: CS402 | B27: Programming Principles | C27: Y1 | D27: Sep | E27: HDC | G27: =G26 -> 20 | H27: =H26 -> 10 | I27: =VLOOKUP($A27,Sheet1!$E:$I,4,0) -> Mr. Mike Wong | J27: =VLOOKUP($A27,Sheet1!$E:$I,5,0) -> FT
A28: CS416 | B28: Computing | C28: Y1 | D28: Sep | E28: HDC | G28: =G27 -> 20 | H28: =H27 -> 10 | I28: =VLOOKUP($A28,Sheet1!$E:$I,4,0) -> Ms. Jo Hugn | J28: =VLOOKUP($A28,Sheet1!$E:$I,5,0) -> FT
A29: GS407 | B29: Mathematics for Computer Science | C29: Y1 | D29: Sep | E29: HDC | G29: =G28 -> 20 | H29: =H28 -> 10 | I29: =VLOOKUP($A29,Sheet1!$E:$I,4,0) -> Dr Kenneth So | J29: =VLOOKUP($A29,Sheet1!$E:$I,5,0) -> FT
A30: EE403 | B30: Electrical Engineering Principles | C30: Y1 | D30: Sep | E30: HDEE | G30: =G29 -> 20 | H30: =H29 -> 10 | I30: =VLOOKUP($A30,Sheet1!$E:$I,4,0) -> Dr Kenneth So | J30: =VLOOKUP($A30,Sheet1!$E:$I,5,0) -> FT
A31: EE409 | B31: Engineering Mathematics | C31: Y1 | D31: Sep | E31: HDEE | G31: =G30 -> 20 | H31: =H30 -> 10 | I31: =VLOOKUP($A31,Sheet1!$E:$I,4,0) -> Dr Kenneth So | J31: =VLOOKUP($A31,Sheet1!$E:$I,5,0) -> FT
A32: CS403 | B32: Introduction to Networks and Computer Security | C32: Y1 | D32: Feb | E32: HDC | F32: Cyber Security | G32: =G31 -> 20 | H32: =H31 -> 10 | I32: =VLOOKUP($A32,Sheet1!$E:$I,4,0) -> Mr. Yuman Chau | J32: =VLOOKUP($A32,Sheet1!$E:$I,5,0) -> PT
A33: CS426 | B33: Data Communications | C33: Y1 | D33: Feb | E33: HDC | F33: Information Systems | G33: =G32 -> 20 | H33: =H32 -> 10 | I33: =VLOOKUP($A33,Sheet1!$E:$I,4,0) -> Mr. Yuman Chau | J33: =VLOOKUP($A33,Sheet1!$E:$I,5,0) -> PT
A34: CS425 | B34: Systems Engineering and Project Management | C34: Y1 | D34: Feb | E34: HDC | F34: Artificial Intelligence | G34: =G33 -> 20 | H34: =H33 -> 10 | I34: =VLOOKUP($A34,Sheet1!$E:$I,4,0) -> Mr. Gary Chan | J34: =VLOOKUP($A34,Sheet1!$E:$I,5,0) -> 0
A35: CS404 | B35: Database Systems | C35: Y1 | D35: Feb | E35: HDC | G35: =G34 -> 20 | H35: =H34 -> 10 | I35: =VLOOKUP($A35,Sheet1!$E:$I,4,0) -> Mr. Mike Wong | J35: =VLOOKUP($A35,Sheet1!$E:$I,5,0) -> FT
A36: CS405 | B36: Data Structures and Algorithms | C36: Y1 | D36: Feb | E36: HDC | G36: =G35 -> 20 | H36: =H35 -> 10 | I36: =VLOOKUP($A36,Sheet1!$E:$I,4,0) -> Mr. Mike Wong | J36: =VLOOKUP($A36,Sheet1!$E:$I,5,0) -> FT
A37: EE402 | B37: Circuit Analysis | C37: Y1 | D37: Feb | E37: HDEE | G37: =G36 -> 20 | H37: =H36 -> 10 | I37: =VLOOKUP($A37,Sheet1!$E:$I,4,0) -> Dr Kenneth So | J37: =VLOOKUP($A37,Sheet1!$E:$I,5,0) -> FT
A38: EE410 | B38: Energy and Power | C38: Y2 | D38: Feb | E38: HDEE | G38: =G37 -> 20 | H38: =H37 -> 10 | I38: =VLOOKUP($A38,Sheet1!$E:$I,4,0) -> Dr Kenneth So | J38: =VLOOKUP($A38,Sheet1!$E:$I,5,0) -> FT
A39: EE406 | B39: Occupation Safety and Site Supervision | C39: Y2 | D39: Jun | E39: HDEE | G39: =G38 -> 20 | H39: =H38 -> 10 | I39: =VLOOKUP($A39,Sheet1!$E:$I,4,0) -> TBC | J39: =VLOOKUP($A39,Sheet1!$E:$I,5,0) -> PT
A40: CS401 | B40: Computational Theory | C40: Y2 | D40: Sep | E40: HDC | G40: =G39 -> 20 | H40: =H39 -> 10 | I40: =VLOOKUP($A40,Sheet1!$E:$I,4,0) -> Mr. Mike Wong | J40: =VLOOKUP($A40,Sheet1!$E:$I,5,0) -> FT
A41: CS407 | B41: Applied Cryptography | C41: Y2 | D41: Sep | E41: HDC | F41: Cyber Security | G41: =G40 -> 20 | H41: =H40 -> 10 | I41: =VLOOKUP($A41,Sheet1!$E:$I,4,0) -> Mr. Ben Wong | J41: =VLOOKUP($A41,Sheet1!$E:$I,5,0) -> PT
A42: CS420 | B42: Programming Language Paradigms | C42: Y2 | D42: Sep | E42: HDC | F42: Information Systems | G42: =G41 -> 20 | H42: =H41 -> 10 | I42: =VLOOKUP($A42,Sheet1!$E:$I,4,0) -> TBC | J42: =VLOOKUP($A42,Sheet1!$E:$I,5,0) -> PT
...

Sheet Sheet1
A1: Programme | B1: Stream | C1: Semester | D1: Module Year | E1: Module Code | F1: Module Name | G1: Mode (N/D/S) | H1: Proposed Teacher | I1: FT/PT | J1: Combined
A2: HD | C2: Sep | D2: Y1 | E2: HD401 | F2: Introduction to Academic English (CEF) | G2: D | H2: Mr Ray Leung | I2: PT
A3: HD | C3: Sep | D3: Y1 | E3: HD401_N | F3: Introduction to Academic English (CEF) | G3: N | H3: Mr Richard Ng | I3: PT
A4: HD | C4: Sep | D4: Y2 | E4: HD404 | F4: Professional Ethics | G4: D | H4: Mr Walter Chan | I4: FT
A5: HD | C5: Sep | D5: Y2 | E5: HD404_N | F5: Professional Ethics | G5: N | H5: Mr Walter Chan | I5: FT
A6: HD | C6: Feb | D6: Y1 | E6: HD402 | F6: Practical Chinese (CEF) | G6: N | H6: Mr Alan Ho | I6: FT
A7: HD | C7: Feb | D7: Y1 | E7: HD402_N | F7: Practical Chinese (CEF) | G7: D | H7: Mr Chris Chau | I7: FT
A8: HD | C8: Feb | D8: Y2 | E8: HD403 | F8: Project Skills | G8: D | H8: Mr Walter Chan | I8: FT
A9: HD | C9: Feb | D9: Y2 | E9: HD403_N | F9: Project Skills | G9: N | H9: Mr Walter Chan | I9: FT
A10: HD | C10: Feb | D10: Y2 | E10: HD405 | F10: English for Communication in Workplace | G10: D | H10: Mr Richard Cheng | I10: PT
A11: HD | C11: Feb | D11: Y2 | E11: HD405_N | F11: English for Communication in Workplace | G11: N | H11: Mr Ray Leung | I11: PT
A12: HDC | C12: Sep | D12: Y1 | E12: CS402 | F12: Programming Principles | G12: D | H12: Mr. Mike Wong | I12: FT
A13: HDC | C13: Sep | D13: Y1 | E13: CS402_N | F13: Programming Principles | G13: N | H13: Mr. Vito Chung | I13: PT
... A18: HDEE | C18: Sep | D18: Y1 | E18: EE409 | F18: Engineering Mathematics | G18: D | H18: Dr Kenneth So | I18: FT
A19: HDC | B19: Cyber Security | C19: Feb | D19: Y1 | E19: CS403 | F19: Introduction to Networks and Computer Security | G19: N | H19: Mr. Yuman Chau | I19: PT | J19: 1
A20: HDC | B20: Information Systems | C20: Feb | D20: Y1 | E20: CS426 | F20: Data Communications | G20: N | H20: Mr. Yuman Chau | I20: PT | J20: 1
A21: HDC | B21: Artificial Intelligence | C21: Feb | D21: Y1 | E21: CS425 | F21: Systems Engineering and Project Management | G21: N | H21: Mr. Gary Chan
A22: HDC | C22: Feb | D22: Y1 | E22: CS404 | F22: Database Systems | G22: D | H22: Mr. Mike Wong | I22: FT | J22: 9
A23: HDC | C23: Feb | D23: Y1 | E23: CS404_N | F23: Database Systems | G23: N | H23: Mr. Vito Chung | I23: PT
A24: HDC | C24: Feb | D24: Y1 | E24: CS405 | F24: Data Structures and Algorithms | G24: D | H24: Mr. Mike Wong | I24: FT
A25: HDC | C25: Feb | D25: Y1 | E25: CS405_N | F25: Data Structures and Algorithms | G25: N | H25: Mr. Vito Chung | I25: PT
A26: HDEE | C26: Feb | D26: Y1 | E26: EE402 | F26: Circuit Analysis | G26: D | H26: Dr Kenneth So | I26: FT
A27: HDEE | C27: Feb | D27: Y1 | E27: EE410 | F27: Energy and Power | G27: D | H27: Dr Kenneth So | I27: FT
A28: HDEE | C28: Jun | D28: Y2 | E28: EE406 | F28: Occupation Safety and Site Supervision | G28: D | H28: TBC | I28: PT
A29: HDC | C29: Sep | D29: Y2 | E29: CS401 | F29: Computational Theory | G29: N | H29: Mr. Mike Wong | I29: FT
A30: HDC | B30: Cyber Security | C30: Sep | D30: Y2 | E30: CS407 | F30: Applied Cryptography | G30: N | H30: Mr. Ben Wong | I30: PT
A31: HDC | B31: Information Systems | C31: Sep | D31: Y2 | E31: CS420 | F31: Programming Language Paradigms | G31: N | H31: TBC | I31: PT
A32: HDC | B32: Cyber Security,Information Systems | C32: Sep | D32: Y2 | E32: CS408 | F32: Artificial Intelligence | G32: N | H32: Dr HK Ng | I32: FT | J32: 8
A33: HDC | B33: Artificial Intelligence | C33: Sep | D33: Y2 | E33: CS423 | F33: Cloud, Distributed Architecture | G33: N | H33: TBC | I33: PT
A34: HDC | B34: Artificial Intelligence | C34: Sep | D34: Y2 | E34: CS422 | F34: Fundamental of Machine Learning | G34: N | H34: Dr Jonathan Lee | I34: PT
A35: HDEE | C35: Sep | D35: Y1 | E35: CS408_EE | F35: Artificial Intelligence | G35: N | H35: Dr HK Ng | I35: FT | J35: 8
A36: HDEE | C36: Sep | D36: Y2 | E36: EE401 | F36: Analogue and Digital Electronics | G36: D | H36: TBC | I36: PT
A37: HDEE | C37: Sep | D37: Y2 | E37: EE404 | F37: Electrical Installations | G37: D | H37: TBC | I37: PT
A38: HDC | B38: Cyber Security | C38: Feb | D38: Y2 | E38: CS406 | F38: Web and Mobile Application Security | G38: N | H38: Mr. Eric Moy | I38: PT
A39: HDC | B39: Cyber Security | C39: Feb | D39: Y2 | E39: CS417 | F39: Introduction to Ethical Hacking Skills | G39: N | H39: Mr. Eric Moy | I39: PT
A40: HDC | B40: Information Systems | C40: Feb | D40: Y2 | E40: CS414 | F40: Internet and Mobile App Development | G40: N | H40: Dr HK Ng | I40: PT
A41: HDC | B41: Information Systems | C41: Feb | D41: Y2 | E41: CS421 | F41: Advanced Algorithms | G41: N | H41: TBC | I41: PT
A42: HDC | B42: Artificial Intelligence | C42: Feb | D42: Y2 | E42: CS424 | F42: Secure Software Development | G42: N | H42: Mr. Ben Wong | I42: PT
A43: HDC | B43: Artificial Intelligence | C43: Feb | D43: Y2 | E43: CS427 | F43: Machine Learning | G43: N | H43: Dr HK Ng | I43: FT
A44: HDEE | C44: Feb | D44: Y1 | E44: EE405 | F44: Transformers and Electrical Machines | H44: TBC | I44: PT
...
